Workbook

Sheet Stores
A1: list | B1: store_name | C1: website | D1: country | E1: city | F1: business_type | G1: shopify_proof | H1: date_app | I1: date_evidence | J1: top_products | K1: contact_email | L1: contact_form_url | M1: instagram | N1: owner_first_name | O1: order_volume_hint | P1: notes | Q1: confidence
A2: main | B2: Muddy's Bake Shop | C2: https://muddysbakeshop.com | D2: United States | E2: Memphis, TN | F2: bakery | G2: App Store review (Zapiet Pickup + Delivery) | H2: Zapiet | I2: Zapiet Pickup + Delivery review says the app coordinates their preorder pickups (review date not visible to me) | P2: Press lists 2497 Broad Ave; walk-ins plus online preorders. Website seen only in press (styleblueprint.com), not opened. Products, email and Instagram not checked. | Q2: medium
A3: main | B3: Dessert Gallery Bakery & Cafe | D3: United States | E3: Houston, TX | F3: bakery and cafe | G3: App Store review (Zapiet Pickup + Delivery) | H3: Zapiet | I3: Zapiet Pickup + Delivery review praising a fast fix (review date not visible to me) | O3: 2 shops (Kirby Dr and The Woodlands); also sells on Goldbelly | P3: Website not found in my search results; check Houston listings. Products not checked. | Q3: medium
A4: main | B4: Clay's Bakery | D4: United States | E4: Berwyn, PA (likely) | F4: bakery | G4: App Store review (Zapiet Pickup + Delivery) | H4: Zapiet | I4: Zapiet review says Zapiet helped set holiday pickup hours (review date not visible to me) | P4: Probably Clay's Creative Corner Bakery, 700 Lancaster Ave, Berwyn PA (6abc, Zola), but the match to the reviewer is unverified. Website not found. | Q4: low
A5: main | B5: Fujiya Hawaii | C5: https://fujiyahawaii.com | D5: United States | E5: Honolulu, HI | F5: mochi and Japanese sweets shop | G5: App Store review (Buunto) | H5: Buunto | I5: Buunto review from Fujiya Hawaii says the app works well for the business (review date not visible to me) | J5: chichi dango; fresh fruit mochi; peanut butter mochi; tsumami mochi; red bean mochi; manju | O5: Shop since 1953; online orders close before big holidays (Hawaii Public Radio, 18 Feb 2026) | P5: Product names come from press articles (onolicioushawaii, Honolulu Magazine), not from the store. Website taken from press, not opened. | Q5: medium
A6: main | B6: Calumet Bakery | C6: https://calumet-bakery.myshopify.com | D6: United States | E6: Chicago, IL (also Whiting and Lansing) | F6: bakery | G6: myshopify.com address | H6: date field, app unknown | I6: Store page says customers must specify the pickup date in the cart; pickup at least 24 hours after order | J6: paczki; nut rolls; coffee cakes; cookies | O6: 3 shops; family business since 1935; ships nut rolls and cookies | P6: Product list is from press (nwitimes), not exact store product names. Public site may be calumetbakery.com (from a listing, not checked). | Q6: medium
A7: main | B7: Balthazar Bakery | C7: https://balthazar-bakery.myshopify.com | D7: United States | F7: bakery | G7: myshopify.com address | H7: not verified | I7: Pre-orders page: pickup only, at least 2 days notice, online orders only. Could not see whether a date picker is used | P7: City not stated in the snippet I saw. Linked to the Balthazar restaurant brand, check it still counts as independent. | Q7: low
A8: main | B8: Mitchell's Ice Cream | C8: https://mitchellsicecream.myshopify.com | D8: United States | E8: San Francisco, CA | F8: ice cream cake maker | G8: myshopify.com address | H8: date field, app unknown | I8: Cake product pages say customers pick a pickup day; earliest pickup is the next day | J8: Mango Ice Cream Cake; Toasted Almond & Mocha Fudge Ice Cream Cake; 7 inch Round All-Ice Cream Cakes | O8: Long-running parlor; also on DoorDash and Uber Eats | P8: Ice cream cakes, not a bakery, but made to order for a chosen day. Public site mitchellsicecream.com (from press). | Q8: medium
A9: main | B9: PDX Cookie Co | C9: https://pdx-cookie-co.myshopify.com | D9: United States | E9: Portland, OR | F9: cookie bakery | G9: myshopify.com address | H9: date field, app unknown | I9: FAQ says pickup is set at checkout and orders cannot be changed after | J9: Chocolate Peanut Butter Bomb | O9: Storefront at 7919 SE Stark St; cookie subscription | P9: Only one product name found (Willamette Week review). Public site may be pdxcookieco.com. | Q9: medium
A10: main | B10: The Cake Boutique | C10: https://the-cake-boutique-nj.myshopify.com | D10: United States | E10: Mullica Hill, NJ | F10: custom cake maker | G10: myshopify.com address | H10: not verified | I10: Homepage says order online and have it ready for pickup; date picker not seen | O10: Also does wedding cakes, cupcakes, cookies, macarons (Zola listing) | P10: Owner name appears on Zola, not on the store site, so I left it empty. | Q10: low
A11: main | B11: Handmade in a Home | C11: https://handmade-in-a-home.myshopify.com | D11: United States | E11: Shafter, CA | F11: home sourdough bakery | G11: myshopify.com address | H11: date field, app unknown | I11: Homepage: customers choose a date, then order; weekly Thursday pickup 3pm to 7pm | O11: Very small home bakery | P11: Products not checked. | Q11: medium
A12: main | B12: Slate Sourdough | C12: https://p0s7rx-iz.myshopify.com | D12: United States | E12: Tulsa, OK | F12: sourdough bakery | G12: myshopify.com address | H12: not verified | I12: Homepage has a pre-order section and online orders for pickup; date choice not seen | P12: Products not checked. | Q12: low
A13: main | B13: The Flying Cupcake | C13: https://the-flying-cupcake-indy.myshopify.com | D13: United States | E13: Indianapolis, IN | F13: cupcake bakery | G13: myshopify.com address | H13: not verified | I13: Has a Pick Up Today collection and ships jars; future date choice not seen | J13: Cupcakes-in-a-Jar | O13: Ships cupcake jars; does not ship Friday to Monday | P13: Only one product name found. | Q13: low
A14: main | B14: dBakers | C14: https://dbakers.us | D14: United States | E14: Miami, FL | F14: bakery | G14: Zapiet case study (Zapiet only works on Shopify) | H14: Zapiet | I14: Zapiet interview: dBakers relies on Zapiet Pickup + Delivery for more than half of its orders (post date not visible to me) | P14: Has a how-to-order page (dbakers.us/pages/how-to-order). Products not checked. | Q14: medium
A15: main | B15: Dead King Bread | C15: https://deadkingbread.myshopify.com | D15: United States | E15: Philadelphia, PA | F15: bakery with bread subscription | G15: myshopify.com address | H15: not verified | I15: Bread subscriptions with pickup or delivery; retail Thu to Sat. Date choice not seen | O15: Bread subscription | P15: Products not checked. | Q15: low
A16: main | B16: Past Time Bakery | C16: https://pasttimebakery.myshopify.com | D16: United States | E16: Brooklyn, NY | F16: cookies and custom cakes | G16: myshopify.com address | H16: not verified | I16: Pickup-only orders; custom cake listed as sold out when crawled | P16: Check it is still active; custom cake was sold out at crawl time. | Q16: low
A17: main | B17: Carol's Cakes | D17: Canada | F17: cake maker | G17: App Store review (Zapiet) | H17: Zapiet | I17: Zapiet review (app and date not clear in the snippet I saw) | P17: Website not found yet. | Q17: low
A18: main | B18: Felix & Norton | D18: Canada | E18: Montreal, QC (likely) | F18: cookie bakery | G18: App Store review (Zapiet) | H18: Zapiet | I18: Zapiet review (date not visible to me) | O18: Several shops (unverified) | P18: Bigger than most; check it still counts as independent. Website not checked. | Q18: low
A19: main | B19: Purebread Bakery | C19: https://purebreadbakery.myshopify.com | D19: Canada | E19: Vancouver, Whistler, Squamish (BC) | F19: bakery | G19: myshopify.com address | H19: not verified | I19: Cakes page: pre-orders need 48 hours, pickup at any of their bakery locations | O19: Several bakery locations | P19: Date picker not seen. Products not checked. | Q19: low
A20: main | B20: Wild Culture Artisan Bakery | C20: https://wildcultureartisanbakery.myshopify.com | D20: Canada | E20: Qualicum Beach, BC | F20: sourdough bakery | G20: myshopify.com address | H20: fixed pickup day | I20: Pre-orders open Sunday 12pm, close Thursday 12pm, for Friday pickup 1pm to 5pm | P20: One fixed pickup day, so the sheet would cover one day a week. Products not checked. | Q20: low
A21: main | B21: Amys Bakehouse | D21: United Kingdom | F21: bakery and catering | G21: App Store review (Zapiet Rates by Zip Code and Product Options) | H21: Zapiet | I21: Zapiet Rates by Zip Code review says it handles catering deliveries and pickup (date not visible to me) | O21: Does catering | P21: Website not found yet. | Q21: low
A22: main | B22: HertfordCakeCo | D22: United Kingdom | E22: Hertford (likely from the name) | F22: cake maker | G22: App Store review (Zapiet) | H22: Zapiet | I22: Zapiet review (date not visible to me) | P22: Website not found yet. | Q22: low
A23: main | B23: Somerset Foodie | C23: https://somerset-foodie.myshopify.com | D23: United Kingdom | E23: Somerset | F23: deli and local food delivery | G23: myshopify.com address | H23: fixed delivery days | I23: Delivery FAQ lists delivery windows by village with order deadlines | O23: Local delivery rounds by village | P23: Not a bakery; fits as a pre-order food delivery business. Products not checked. | Q23: low
A24: main | B24: Singl-End Bakehouse | C24: https://singl-end-bakehouse.myshopify.com | D24: United Kingdom | E24: Glasgow | F24: bakehouse and cafe | G24: myshopify.com address | H24: date field, app unknown | I24: Bespoke cakes page: collection only on Friday or Saturday 10am to 3pm, at least 7 days notice | O24: Cafe plus bakehouse | P24: Whether a picker or a note is used was not visible. Products not checked. | Q24: medium
A25: main | B25: Bramble & Crumb | D25: United Kingdom | E25: South London | F25: artisan bakery | G25: Zapiet case study (Zapiet only works on Shopify) | H25: Zapiet | I25: Zapiet case study: set up delivery zones, pickup windows and scheduling | O25: Case study claims 40% more local delivery sales (vendor figure) | P25: Website not found yet. | Q25: low
A26: main | B26: Pavilion Bakery | D26: United Kingdom | E26: Newquay, Cornwall | F26: bakery | G26: Dewsign case study (Shopify store with Zapiet) | H26: Zapiet | I26: Dewsign case study: click and collect built with Shopify, Kosmos POS and Zapiet | O26: Case study title says 15 years of growth | P26: Website not found yet. | Q26: medium
A27: main | B27: Freshly Prepd | C27: https://freshlyprepd.myshopify.com | D27: Ireland | F27: meal prep | G27: myshopify.com address | H27: fixed delivery days | I27: Pickup Monday and Wednesday; delivery ships Sunday for Monday | O27: Delivers across Ireland | P27: Fixed days, not a free date choice. Products not checked. | Q27: low
A28: main | B28: A Slice of Jodie | D28: Australia | F28: cake maker | G28: App Store review (Zapiet Product Options) | H28: Zapiet (Product Options only) | I28: Zapiet Product Options review says the store would not exist without the app; no date app seen | P28: Product Options is not a date picker, so date choice is unverified. Website not found yet. | Q28: low
A29: main | B29: Tanna Sweets | D29: Australia | F29: sweets and desserts | G29: App Store review (Pickeasy) | H29: Pickeasy | I29: Pickeasy review (date not visible to me) | P29: Website not found yet. | Q29: low
A30: main | B30: The Cupcake Room | D30: Australia | E30: Sydney | F30: cupcake bakery | G30: Zapiet blog story (Zapiet only works on Shopify) | H30: Zapiet | I30: Zapiet blog (2021): owner uses per-product prep times and pickup slots | O30: Owner reported revenue up almost 500% after moving to Shopify (2021, self-reported) | P30: Story is from 2021; check it is still active. Website not found yet. | Q30: low
A31: main | B31: Workout Meals | C31: https://workoutmeals.myshopify.com | D31: Australia | F31: meal prep | G31: myshopify.com address | H31: fixed delivery days | I31: 11pm AEST cutoff for the next delivery; flexible delivery days for subscribers | J31: Air Fryer Pack | O31: Delivers to over 3000 suburbs Australia-wide | P31: Larger than most on this list. Products mostly not checked. | Q31: low
A32: main | B32: Clementine Bakery | C32: https://clementinebakery.myshopify.com | D32: Australia | E32: Yass, NSW | F32: bakery | G32: myshopify.com address | H32: date field, app unknown | I32: Collection pages list pickup dates by location, for example pickup from the Yass bakery from 9am | O32: More than one pickup location | P32: Products not checked. | Q32: medium
A33: main | B33: Butterdream Baking | C33: https://butterdreambaking.myshopify.com | D33: Australia | E33: Carramar, WA | F33: cakes and cookies | G33: myshopify.com address | H33: not verified | I33: Homepage: order online and collect from their Carramar kitchen; date choice not seen | P33: Products not checked. | Q33: low
A34: backup | B34: Bread by Us | C34: https://bread-by-us.myshopify.com | F34: bakery | G34: myshopify.com address | H34: date field, app unknown | I34: FAQ: at checkout the customer picks one pickup day, Wednesday to Sunday; order by 2pm the day before | P34: backup: country not confirmed (has an English FAQ page, so may be bilingual). | Q34: low
A35: backup | B35: Sweet Oven Delights | C35: https://sweetovendelights.myshopify.com | F35: cupcakes | G35: myshopify.com address | H35: note field only | I35: Cupcake page asks buyers to type the pickup date in the special instructions box | J35: Cupcakes | P35: backup: country not confirmed (prices look like USD); uses a note, not a picker. That still fits PrepDay only if notes can be parsed. | Q35: low
A36: backup | B36: Flour & Rise | C36: https://flourandrise.myshopify.com | F36: roadside sourdough stand | G36: myshopify.com address | H36: fixed pickup day | I36: Preorder windows with one set pickup date, for example pickup on 10/18 | O36: Open 2nd and 4th Sunday | P36: backup: country not confirmed; very small. | Q36: low
A37: backup | B37: Jenny's Crust & Crumb | C37: https://crust-crumb-sourdough-co-nwa.myshopify.com | D37: United States | E37: Northwest Arkansas | F37: sourdough bakery | G37: myshopify.com address | H37: none | I37: Pickup date is emailed after the order is reviewed; customer does not choose it | P37: backup: fails the date-choice rule. | Q37: low
A38: backup | B38: The Clean Pantry | C38: https://the-clean-pantry.myshopify.com | D38: Canada (CAD prices) | F38: health food store with bakery pre-orders | G38: myshopify.com address | H38: note field only | I38: Bakery pre-orders ready about a week later; specific date requested in order comments | P38: backup: country inferred from CAD prices only. | Q38: low
A39: backup | B39: HalalMeals | C39: https://halal-meals.myshopify.com | D39: Canada | E39: Ontario and Montreal | F39: meal prep | G39: myshopify.com address | H39: not verified | I39: Weekly changing menu; delivery date selector not seen | O39: Serves Ontario and Montreal | P39: backup: date choice unverified. | Q39: low
A40: backup | B40: Betty Bakery | C40: https://betty-bakery.myshopify.com | F40: bakery | G40: myshopify.com address | H40: not verified | I40: Cakes page: pick up in as little as 2 days | P40: backup: country unknown. | Q40: low
...

Sheet Summary
A1: PrepDay early access list: counts (formulas read the Stores tab)
A3: List | B3: Stores
A4: main | B4: =COUNTIF(Stores!$A$2:$A$43,A4) -> 32
A5: backup | B5: =COUNTIF(Stores!$A$2:$A$43,A5) -> 10
A6: Total | B6: =SUM(B4:B5) -> 42
A8: Date app (main list) | B8: Stores
A9: Zapiet | B9: =COUNTIFS(Stores!$A$2:$A$43,"main",Stores!$H$2:$H$43,A9) -> 11
A10: Zapiet (Product Options only) | B10: =COUNTIFS(Stores!$A$2:$A$43,"main",Stores!$H$2:$H$43,A10) -> 1
A11: Buunto | B11: =COUNTIFS(Stores!$A$2:$A$43,"main",Stores!$H$2:$H$43,A11) -> 1
A12: Pickeasy | B12: =COUNTIFS(Stores!$A$2:$A$43,"main",Stores!$H$2:$H$43,A12) -> 1
A13: date field, app unknown | B13: =COUNTIFS(Stores!$A$2:$A$43,"main",Stores!$H$2:$H$43,A13) -> 6
A14: fixed delivery days | B14: =COUNTIFS(Stores!$A$2:$A$43,"main",Stores!$H$2:$H$43,A14) -> 3
A15: fixed pickup day | B15: =COUNTIFS(Stores!$A$2:$A$43,"main",Stores!$H$2:$H$43,A15) -> 1
A16: not verified | B16: =COUNTIFS(Stores!$A$2:$A$43,"main",Stores!$H$2:$H$43,A16) -> 8
A17: Total | B17: =SUM(B9:B16) -> 32
A19: Country (main list) | B19: Stores
A20: United States | B20: =COUNTIFS(Stores!$A$2:$A$43,"main",Stores!$D$2:$D$43,A20) -> 15
A21: United Kingdom | B21: =COUNTIFS(Stores!$A$2:$A$43,"main",Stores!$D$2:$D$43,A21) -> 6
A22: Australia | B22: =COUNTIFS(Stores!$A$2:$A$43,"main",Stores!$D$2:$D$43,A22) -> 6
A23: Canada | B23: =COUNTIFS(Stores!$A$2:$A$43,"main",Stores!$D$2:$D$43,A23) -> 4
A24: Ireland | B24: =COUNTIFS(Stores!$A$2:$A$43,"main",Stores!$D$2:$D$43,A24) -> 1
A25: New Zealand | B25: =COUNTIFS(Stores!$A$2:$A$43,"main",Stores!$D$2:$D$43,A25) -> 0
A27: Confidence (main list) | B27: Stores
A28: high | B28: =COUNTIFS(Stores!$A$2:$A$43,"main",Stores!$Q$2:$Q$43,A28) -> 0
A29: medium | B29: =COUNTIFS(Stores!$A$2:$A$43,"main",Stores!$Q$2:$Q$43,A29) -> 11
A30: low | B30: =COUNTIFS(Stores!$A$2:$A$43,"main",Stores!$Q$2:$Q$43,A30) -> 21
A32: How to read this file:
A33: Stores tab: one row per business. Column A says main or backup. Filter with the arrows in row 1.
A34: Confidence colors: yellow = medium, red = low. No store is high yet, because the store websites could not be opened during research (25 Oct 2026).
A35: Empty cells were not checked. Nothing was guessed. Fill them by running verify_bakeries.py, then re-import.
A36: Source of every row: date-app reviews on the Shopify App Store, Zapiet case studies, or myshopify.com store pages.
